Workbook
Name tgr: WACC!$B$10
Name wacc: WACC!$B$23

Sheet DCF
A3: DCF model
A5: Overview
A13: Assumptions
A15: Selected Case | B15: 1
A17: Base Case | B17: 1
A18: Conservative Case | B18: 2
A19: Optimistic Case | B19: 3
A22: Income statement
H25: Actuals | M25: Projection
A26: $M | H26: 2020 | I26: =H26+1 -> 2021 | J26: =I26+1 -> 2022 | K26: =J26+1 -> 2023 | L26: =K26+1 -> 2024 | M26: =L26+1 -> 2025 | N26: =M26+1 -> 2026 | O26: =N26+1 -> 2027 | P26: =O26+1 -> 2028 | ... R26: =Q26+1 -> 2030
A27: Revenue | H27: =IS!F2 -> 16849 | I27: =IS!G2 -> 19647 | J27: =IS!H2 -> 22058 | K27: =IS!I2 -> 23581 | L27: =IS!J2 -> 23962 | M27: =L27*(1+M28) -> 24561.05 | N27: =M27*(1+N28) -> 25175.076 | O27: =N27*(1+O28) -> 25804.453 | P27: =O27*(1+P28) -> 26449.564 | Q27: =P27*(1+Q28) -> 27110.804 | R27: =Q27*(1+R28) -> 27788.574
A28: % growth | I28: =I27/H27-1 -> 0.16606327 | J28: =J27/I27-1 -> 0.12271594 | K28: =K27/J27-1 -> 0.069045244 | L28: =L27/K27-1 -> 0.016157076 | M28: =CHOOSE($B$15,M29,M30,M31) -> 0.025 | N28: =CHOOSE($B$15,N29,N30,N31) -> 0.025 | O28: =CHOOSE($B$15,O29,O30,O31) -> 0.025 | P28: =CHOOSE($B$15,P29,P30,P31) -> 0.025 | Q28: =CHOOSE($B$15,Q29,Q30,Q31) -> 0.025 | R28: =CHOOSE($B$15,R29,R30,R31) -> 0.025
A29: Base Case | M29: 0.025 | N29: 0.025 | O29: 0.025 | P29: 0.025 | Q29: 0.025 | R29: 0.025
A30: Conservative Case | M30: 0.02 | N30: 0.02 | O30: 0.02 | P30: 0.02 | Q30: 0.02 | R30: 0.02
A31: Optimistic Case | M31: 0.039 | N31: 0.039 | O31: 0.039 | P31: 0.039 | Q31: 0.039 | R31: 0.039
A33: COGS | H33: =IS!F4 -> 6788 | I33: =IS!G4 -> 7482 | J33: =IS!H4 -> 7831 | K33: =IS!I4 -> 8419 | L33: =IS!J4 -> 8525 | M33: =M27-M35 -> 8516.6041 | N33: =N27-N35 -> 8499.2814 | O33: =O27-O35 -> 8472.4657 | P33: =P27-P35 -> 8435.5634 | Q33: =Q27-Q35 -> 8387.9515 | R33: =R27-R35 -> 8328.9774
A35: Gross Profit | H35: =H27-H33 -> 10061 | I35: =I27-I33 -> 12165 | J35: =J27-J33 -> 14227 | K35: =K27-K33 -> 15162 | L35: =L27-L33 -> 15437 | M35: =M27*M36 -> 16044.446 | N35: =N27*N36 -> 16675.795 | O35: =O27*O36 -> 17331.987 | P35: =P27*P36 -> 18014.001 | Q35: =Q27*Q36 -> 18722.852 | R35: =R27*R36 -> 19459.596
A36: % margin | H36: =H35/H27 -> 0.59712743 | I36: =I35/I27 -> 0.6191785 | J36: =J35/J27 -> 0.64498141 | K36: =K35/K27 -> 0.64297528 | L36: =L35/L27 -> 0.64422836 | M36: =L36*(1+M37) -> 0.65324756 | N36: =M36*(1+N37) -> 0.66239302 | O36: =N36*(1+O37) -> 0.67166653 | P36: =O36*(1+P37) -> 0.68106986 | Q36: =P36*(1+Q37) -> 0.69060484 | R36: =Q36*(1+R37) -> 0.7002733
M37: =CHOOSE($B$15,M38,M39,M40) -> 0.014 | N37: =CHOOSE($B$15,N38,N39,N40) -> 0.014 | O37: =CHOOSE($B$15,O38,O39,O40) -> 0.014 | P37: =CHOOSE($B$15,P38,P39,P40) -> 0.014 | Q37: =CHOOSE($B$15,Q38,Q39,Q40) -> 0.014 | R37: =CHOOSE($B$15,R38,R39,R40) -> 0.014
A38: Base Case | M38: 0.014 | N38: 0.014 | O38: 0.014 | P38: 0.014 | Q38: 0.014 | R38: 0.014
A39: Conservative Case | M39: 0 | N39: 0 | O39: 0 | P39: 0 | Q39: 0 | R39: 0
A40: Optimistic Case | M40: 0.03 | N40: 0.03 | O40: 0.03 | P40: 0.03 | Q40: 0.03 | R40: 0.03
A42: Opex | H42: =IS!F9 -> 2243 | I42: =IS!G9 -> 2316 | J42: =IS!H9 -> 2595 | K42: =IS!I9 -> 2492 | L42: =IS!J9 -> 2535 | M42: =M35-M44 -> 2535.8684 | N42: =N35-N44 -> 2829.503 | O42: =O35-O44 -> 2881.4937 | P42: =P35-P44 -> 3202.245 | Q42: =Q35-Q44 -> 2998.586 | R42: =R35-R44 -> 3342.2236
A44: EBITDA | H44: =H35-H42 -> 7818 | I44: =I35-I42 -> 9849 | J44: =J35-J42 -> 11632 | K44: =K35-K42 -> 12670 | L44: =L35-L42 -> 12902 | M44: =M27*M45 -> 13508.578 | N44: =N27*N45 -> 13846.292 | O44: =O27*O45 -> 14450.494 | P44: =P27*P45 -> 14811.756 | Q44: =Q27*Q45 -> 15724.266 | R44: =R27*R45 -> 16117.373
A45: % margin | H45: =H44/H27 -> 0.4640038 | I45: =I44/I27 -> 0.50129791 | J45: =J44/J27 -> 0.52733702 | K45: =K44/K27 -> 0.53729698 | L45: =L44/L27 -> 0.53843586 | M45: =CHOOSE($B$15,M46,M47,M48) -> 0.55 | N45: =CHOOSE($B$15,N46,N47,N48) -> 0.55 | O45: =CHOOSE($B$15,O46,O47,O48) -> 0.56 | P45: =CHOOSE($B$15,P46,P47,P48) -> 0.56 | Q45: =CHOOSE($B$15,Q46,Q47,Q48) -> 0.58 | R45: =CHOOSE($B$15,R46,R47,R48) -> 0.58
A46: Base Case | M46: 0.55 | N46: 0.55 | O46: 0.56 | P46: 0.56 | Q46: 0.58 | R46: 0.58
A47: Conservative Case | M47: 0.52 | N47: 0.52 | O47: 0.51 | P47: 0.51 | Q47: 0.5 | R47: 0.5
A48: Optimistic Case | M48: 0.55 | N48: 0.56 | O48: 0.57 | P48: 0.59 | Q48: 0.6 | R48: 0.61
A50: D&A | H50: =IS!F5 -> 1536 | I50: =IS!G5 -> 1580 | J50: =IS!H5 -> 1780 | K50: =IS!I5 -> 1830 | L50: =IS!J5 -> 1939 | M50: =M27*M51 -> 1964.884 | N50: =N27*N51 -> 2014.0061 | O50: =O27*O51 -> 2064.3563 | P50: =P27*P51 -> 2115.9652 | Q50: =Q27*Q51 -> 2168.8643 | R50: =R27*R51 -> 2223.0859
A51: % of sales | H51: =H50/H27 -> 0.09116268 | I51: =I50/I27 -> 0.080419402 | J51: =J50/J27 -> 0.080696346 | K51: =K50/K27 -> 0.077604851 | L51: =L50/L27 -> 0.08091979 | M51: =CHOOSE($B$15,M52,M53,M54) -> 0.08 | N51: =CHOOSE($B$15,N52,N53,N54) -> 0.08 | O51: =CHOOSE($B$15,O52,O53,O54) -> 0.08 | P51: =CHOOSE($B$15,P52,P53,P54) -> 0.08 | Q51: =CHOOSE($B$15,Q52,Q53,Q54) -> 0.08 | R51: =CHOOSE($B$15,R52,R53,R54) -> 0.08
A52: Base Case | M52: 0.08 | N52: 0.08 | O52: 0.08 | P52: 0.08 | Q52: 0.08 | R52: 0.08
A53: Conservative Case | M53: 0.07 | N53: 0.07 | O53: 0.07 | P53: 0.07 | Q53: 0.07 | R53: 0.07
A54: Optimistic Case | M54: 0.09 | N54: 0.09 | O54: 0.09 | P54: 0.09 | Q54: 0.09 | R54: 0.09
A56: EBIT | H56: =H44-H50 -> 6282 | I56: =I44-I50 -> 8269 | J56: =J44-J50 -> 9852 | K56: =K44-K50 -> 10840 | L56: =L44-L50 -> 10963 | M56: =M44-M50 -> 11543.694 | N56: =N44-N50 -> 11832.286 | O56: =O44-O50 -> 12386.138 | ... R56: =R44-R50 -> 13894.287
A57: % margin | H57: =H56/H27 -> 0.37284112 | I57: =I56/I27 -> 0.42087851 | J57: =J56/J27 -> 0.44664067 | K57: =K56/K27 -> 0.45969213 | L57: =L56/L27 -> 0.45751607 | M57: =M56/M27 -> 0.47 | N57: =N56/N27 -> 0.47 | O57: =O56/O27 -> 0.48 | ... R57: =R56/R27 -> 0.5
A59: Interests | H59: =IS!F16 -> 1075 | I59: =IS!G16 -> 1010 | J59: =IS!H16 -> 1236 | K59: =IS!I16 -> 1297 | L59: =IS!J16 -> 1435 | M59: =M27*M60 -> 1470.875 | N59: =N27*N60 -> 1507.6469 | O59: =O27*O60 -> 1545.338 | P59: =P27*P60 -> 1583.9715 | Q59: =Q27*Q60 -> 1623.5708 | R59: =R27*R60 -> 1664.1601
A60: % of sales | H60: =H59/H27 -> 0.063802006 | I60: =I59/I27 -> 0.05140734 | J60: =J59/J27 -> 0.056034092 | K60: =K59/K27 -> 0.055001908 | L60: =L59/L27 -> 0.059886487 | M60: =L60 -> 0.059886487 | N60: =M60 -> 0.059886487 | O60: =N60 -> 0.059886487 | P60: =O60 -> 0.059886487 | Q60: =P60 -> 0.059886487 | R60: =Q60 -> 0.059886487
A62: Taxable income | H62: =H56-H59 -> 5207 | I62: =I56-I59 -> 7259 | J62: =J56-J59 -> 8616 | K62: =K56-K59 -> 9543 | L62: =L56-L59 -> 9528 | M62: =M56-M59 -> 10072.819 | N62: =N56-N59 -> 10324.639 | O62: =O56-O59 -> 10840.799 | ... R62: =R56-R59 -> 12230.127
A63: % margin | H63: =H62/H27 -> 0.30903911 | I63: =I62/I27 -> 0.36947117 | J63: =J62/J27 -> 0.39060658 | K63: =K62/K27 -> 0.40469022 | L63: =L62/L27 -> 0.39762958 | M63: =M62/M27 -> 0.41011351 | N63: =N62/N27 -> 0.41011351 | O63: =O62/O27 -> 0.42011351 | ... R63: =R62/R27 -> 0.44011351
A65: Taxes | H65: =IS!F22 -> 1237 | I65: =IS!G22 -> 1339 | J65: =IS!H22 -> 1566 | K65: =IS!I22 -> 1899 | L65: =IS!J22 -> 1961 | M65: =M62*M66 -> 2031.8664 | N65: =N62*N66 -> 2082.6631 | O65: =O62*O66 -> 2186.7818 | P65: =P62*P66 -> 2241.4514 | Q65: =Q62*Q66 -> 2406.8623 | R65: =R62*R66 -> 2467.0339
...

Sheet INPUT>>>

Sheet IS
A1: Line Item | B1: 46372 | C1: 46373 | D1: 46374 | E1: 46375 | F1: 46376 | G1: 46377 | H1: 46378 | I1: 46379 | J1: 46380 | K1: Sep-25 LTM
A2: Sales | B2: 22258 | C2: 20232 | D2: 17822 | E2: 19086 | F2: 16849 | G2: 19647 | H2: 22058 | I2: 23581 | J2: 23962 | K2: 23790
A3: Cost of Goods Sold (COGS) incl. D&A | B3: 13033 | C3: 10816 | D3: 8679 | E3: 9134 | F3: 8324 | G3: 9063 | H3: 9611 | I3: 10249 | J3: 10463 | K3: 10171
A4: COGS excluding D&A | B4: 11662 | C4: 9607 | D4: 7423 | E4: 7689 | F4: 6788 | G4: 7482 | H4: 7831 | I4: 8419 | J4: 8525 | K4: 8200
A5: Depreciation & Amortization Expense | B5: 1371 | C5: 1209 | D5: 1256 | E5: 1446 | F5: 1536 | G5: 1580 | H5: 1780 | I5: 1830 | J5: 1939 | K5: 1971
A6: Depreciation | B6: 1257 | C6: 1088 | D6: 1104 | E6: 1244 | F6: 1289 | G6: 1295 | H6: 1383 | I6: 1389 | J6: 1387 | K6: 1387
A7: Amortization of Intangibles | B7: 114 | C7: 120 | D7: 152 | E7: 202 | F7: 247 | G7: 285 | H7: 396 | I7: 441 | J7: 552 | K7: 580
A8: Gross Income | B8: 9225 | C8: 9416 | D8: 9143 | E8: 9954 | F8: 8525 | G8: 10585 | H8: 12447 | I8: 13332 | J8: 13499 | K8: 13619
A9: SG&A Expense | B9: 2156 | C9: 1978 | D9: 1865 | E9: 2021 | F9: 2243 | G9: 2316 | H9: 2595 | I9: 2492 | J9: 2535 | K9: 2640
A10: Other SG&A | B10: 2156 | C10: 1978 | D10: 1865 | E10: 2021 | F10: 2243 | G10: 2316 | H10: 2595 | I10: 2492 | J10: 2535 | K10: 2640
A11: EBIT (Operating Income) | B11: 7069 | C11: 7438 | D11: 7278 | E11: 7932 | F11: 6283 | G11: 8269 | H11: 9852 | I11: 10840 | J11: 10964 | K11: 10978
A12: Nonoperating Income - Net | B12: 218 | C12: 296 | D12: 356 | E12: 267 | F12: 43 | G12: 118 | H12: 1263 | I12: 861 | J12: 272 | K12: 2168
A13: Nonoperating Interest Income | B13: 4 | C13: 6 | D13: 3 | E13: 3 | F13: 16 | G13: 8 | H13: 42 | I13: 172 | J13: 95 | K13: 73
... A24: Net Income | B24: 4237 | C24: 4603 | D24: 5022 | E24: 5383 | F24: 4150 | G24: 6384 | H24: 5878 | I24: 7833 | J24: 7602 | K24: 7623
A28: Capex | F28: 1354 | G28: 1830 | H28: 1749 | I28: 2198 | J28: 2690 | K28: 2707 | L28: 2928 | M28: 3261 | N28: 3525 | O28: =N28*(1+O30) -> 3774.0819 | P28: =O28*(1+P30) -> 4040.7644
A29: % of sales | F29: =F28/DCF!H27 -> 0.080360852 | G29: =G28/DCF!I27 -> 0.093143991 | H29: =H28/DCF!J27 -> 0.07929096 | I29: =I28/DCF!K27 -> 0.093210636 | J29: =J28/DCF!L27 -> 0.11226108 | K29: =K28/DCF!M27 -> 0.11021516 | L29: =L28/DCF!N27 -> 0.11630551 | M29: =M28/DCF!O27 -> 0.12637354 | N29: =N28/DCF!P27 -> 0.13327252 | O29: =AVERAGE(K29:N29) -> 0.12154168 | P29: =AVERAGE(L29:O29) -> 0.12437331
A30: % growth | G30: =G28/F28-1 -> 0.35155096 | H30: =H28/G28-1 -> -0.044262295 | I30: =I28/H28-1 -> 0.25671812 | J30: =J28/I28-1 -> 0.22383985 | K30: =K28/J28-1 -> 0.0063197026 | L30: =L28/K28-1 -> 0.081640192 | M30: =M28/L28-1 -> 0.11372951 | N30: =N28/M28-1 -> 0.080956762 | O30: =AVERAGE(K30:N30) -> 0.070661541 | P30: =O30 -> 0.070661541

Sheet BS
A1: Line Item | B1: 46371 | C1: 46372 | D1: 46373 | E1: 46374 | F1: 46375 | G1: 46376 | H1: 46377 | I1: 46378 | J1: 46379 | K1: 46380
A2: ASSETS
A3: Cash & Short-Term Investments | B3: 7075 | C3: 1160 | D3: 2052 | E3: 758 | F3: 800 | G3: 2819 | H3: 4141 | I3: 2421 | J3: 4145 | K3: 1048
A4: Short-Term Receivables | B4: 1196 | C4: 1398 | D4: 1646 | E4: 2136 | F4: 1981 | G4: 1725 | H4: 1647 | I4: 1982 | J4: 2252 | K4: 2301
A5: Inventories | B5: 92 | C5: 56 | D5: 49 | E5: 45 | F5: 45 | G5: 42 | H5: 49 | I5: 49 | J5: 48 | K5: 54
A6: Other Current Assets | B6: 514 | C6: 1984 | D6: 690 | E6: 608 | F6: 343 | G6: 517 | H6: 450 | I6: 631 | J6: 784 | K6: 1037
A7: Total Current Assets | B7: 8877 | C7: 4597 | D7: 4436 | E7: 3546 | F7: 3170 | G7: 5103 | H7: 6286 | I7: 5082 | J7: 7230 | K7: 4440
A8: Net PP&E | B8: 21281 | C8: 20154 | D8: 18694 | E8: 19982 | F8: 33337 | G8: 31699 | H8: 33655 | I8: 34049 | J8: 34782 | K8: 37310
A9: Long-Term Investments | B9: 864 | C9: 692 | D9: 1044 | E9: 1056 | F9: 1310 | G9: 1089 | H9: 1265 | I9: 1024 | J9: 1151 | K9: 2656
A10: Intangible Assets | B10: 2316 | C10: 2215 | D10: 1982 | E10: 2040 | F10: 2978 | G10: 2831 | H10: 3146 | I10: 3527 | J10: 3509 | K10: 3913
A11: Deferred Tax Assets | B11: 490 | C11: 762 | D11: 723 | E11: 1067 | F11: 1015 | G11: 1745 | H11: 2073 | I11: 2321 | J11: 2737 | K11: 3422
A12: Other Assets | B12: 1096 | C12: 993 | D12: 1272 | E12: 1013 | F12: 516 | G12: 543 | H12: 933 | I12: 1253 | J12: 1419 | K12: 1550
A13: Total Assets | B13: 34925 | C13: 29414 | D13: 28151 | E13: 28702 | F13: 42326 | G13: 43012 | H13: 47357 | I13: 47258 | J13: 50828 | K13: 53290
A15: LIABILITIES
A16: ST Debt & Current Portion LT Debt | B16: 0 | C16: 73 | D16: 0 | E16: 0 | F16: 606 | G16: 2407 | H16: 620 | I16: 619 | J16: 2608 | K16: 614
A17: Accounts Payable | B17: 805 | C17: 717 | D17: 770 | E17: 1057 | F17: 880 | G17: 606 | H17: 885 | I17: 918 | J17: 998 | K17: 994
A18: Income Tax Payable | B18: 143 | C18: 253 | D18: 221 | E18: 200 | F18: 296 | G18: 606 | H18: 317 | I18: 258 | J18: 638 | K18: 349
A19: Other Current Liabilities | B19: 1768 | C19: 2245 | D19: 1416 | E19: 1345 | F19: 1444 | G19: 1433 | H19: 1712 | I19: 1767 | J19: 1965 | K19: 1772
A20: Total Current Liabilities | B20: 2716 | C20: 3288 | D20: 2407 | E20: 2601 | F20: 3226 | G20: 5052 | H20: 3535 | I20: 3563 | J20: 6209 | K20: 3729
A21: Long-Term Debt | B21: 22206 | C21: 24535 | D21: 24597 | E21: 27184 | F21: 41760 | G21: 39654 | H21: 42775 | I21: 45011 | J21: 45454 | K21: 49553
A22: Deferred Tax Liabilities | B22: 1569 | C22: 1723 | D22: 932 | E22: 1063 | F22: 1174 | G22: 1656 | H22: 1825 | I22: 1872 | J22: 1522 | K22: 1848
A23: Other Liabilities | B23: 1909 | C23: 1957 | D23: 2936 | E23: 3329 | F23: 3480 | G23: 3046 | H23: 3268 | I23: 2438 | J23: 1904 | K23: 1827
A24: Total Liabilities | B24: 28400 | C24: 31503 | D24: 30873 | E24: 34177 | F24: 49640 | G24: 49407 | H24: 51403 | I24: 52883 | J24: 55088 | K24: 56957
A26: SHAREHOLDERS' EQUITY
A27: Common Stock / Par Value | B27: 15 | C27: 16 | D27: 14 | E27: 15 | F27: 15 | G27: 14 | H27: 15 | I27: 16 | J27: 15 | K27: 16
A28: Additional Paid-In Capital | B28: 6014 | C28: 6107 | D28: 5890 | E28: 6415 | F28: 6819 | G28: 6460 | H28: 7238 | I28: 8009 | J28: 8050 | K28: 8963
A29: Retained Earnings | B29: 41052 | C29: 43823 | D29: 40245 | E29: 44165 | F29: 47154 | G29: 44059 | H29: 50593 | I29: 55792 | J29: 57466 | K29: 64543
A30: Treasury Stock | B30: -37906 | C30: -49404 | D30: -47056 | E30: -53824 | F30: -59090 | G30: -54813 | H30: -59629 | I30: -67111 | J30: -67569 | K30: -74722
A31: Other Equity Items (Net) | B31: -2650 | C31: -2632 | D31: -1815 | E31: -2246 | F31: -2212 | G31: -2115 | H31: -2263 | I31: -2331 | J31: -2223 | K31: -2467
A32: Total Equity | B32: 6525 | C32: -2090 | D32: -2722 | E32: -5475 | F32: -7314 | G32: -6395 | H32: -4046 | I32: -5625 | J32: -4261 | K32: -3667
A33: Total Liabilities & Equity | B33: 34925 | C33: 29414 | D33: 28151 | E33: 28702 | F33: 42326 | G33: 43012 | H33: 47357 | I33: 47258 | J33: 50828 | K33: 53290

Sheet WACC
A3: WACC
A5: Formula = | B5: Ke*Equity/(debt + equity) + Kdat*Debt/(debt + equity)
A7: Ke = | B7: Cost of equity
A8: Ke = | B8: Rf + Beta (Rm - Rf)
A10: Rf | B10: 0.045 | C10: 10 yr treas yield - google
A11: Beta | B11: 0.7 | C11: factset
A12: MRP | B12: 0.046 | C12: damodran
A13: Ke | B13: =tgr+B11*B12 -> 0.0772
A15: kdat = | B15: cost of debt after tax
A16: kdat = | B16: 0.06
A18: equity | B18: 217140 | C18: Yahoo finance
A19: debt | B19: 49533
A20: equity % | B20: =B18/(B18+B19) -> 0.81425566
A21: debt % | B21: =1-B20 -> 0.18574434
A23: WACC | B23: =B13*B20+B21*B16 -> 0.074005197
